<?xml version="1.0" encoding="utf-8"?>
<!-- =================================================================================== -->
<!-- |    This document was autogenerated by xacro from urdf/spotmicroai.urdf.xacro    | -->
<!-- |    EDITING THIS FILE BY HAND IS NOT RECOMMENDED                                 | -->
<!-- =================================================================================== -->
<robot name="SpotMicroAI">
  <material name="yellow">
    <color rgba="0.92 0.83 0.0 1"/>
  </material>
  <material name="black">
    <color rgba="0.1 0.1 0.1 1"/>
  </material>
  <material name="grey">
    <color rgba="0.65 0.26 0.043 0.39"/>
  </material>
  <material name="blue">
    <color rgba="0.0 0.0 1.0 1"/>
  </material>
  <material name="green_dark">
    <color rgba="0.0 0.5 0.0 1"/>
  </material>
  <!-- Params -->
  <!-- Macros -->
  <!-- Robot Body -->
  <link name="base_link">
  </link>

  <link name="body_link">
    <visual>
      <geometry>
        <mesh filename="package://spot_micro_description/urdf/stl/mainbody.stl" scale="0.001 0.001 0.001"/>
      </geometry>
      <material name="black"/>
      <origin rpy="0 0 0" xyz="-0.045 -0.060 -0.015"/>
    </visual>
    <collision>
      <geometry>
        <box size="0.14 0.11 0.07"/>
      </geometry>
      <origin rpy="0 0 0" xyz="0 0 0"/>
    </collision>
    <inertial>
      <mass value="2.80"/>
      <inertia ixx="0.003966" ixy="0" ixz="0" iyy="0.0057166" iyz="0" izz="0.0056466"/>
    </inertial>
  </link>

  <joint name="base_link_joint" type="fixed">
      <origin rpy="0 0 0" xyz="0 0 0" />
      <parent link="base_link" />
      <child link="body_link" />
  </joint>



  <!-- Lidar Backpack -->
  <link name="lidar_link">
    <visual>
      <geometry>
        <mesh filename="package://spot_micro_description/urdf/stl/rplidar.dae" scale="0.8 0.8 0.8"/>
      </geometry>
      <material name="black"/>
      <origin rpy="0 0 0" xyz="0 -0.005 0"/>
    </visual>
    <collision>
      <geometry>
        <cylinder length="0.05" radius="0.08"/>
      </geometry>
      <origin rpy="0 0 0" xyz="0 -0.01 0"/>
    </collision>
    <inertial>
      <mass value="0.50"/>
      <inertia ixx="0.000904" ixy="0" ixz="0" iyy="0.000904" iyz="0" izz="0.0016"/>
    </inertial>
  </link>

  <joint name="base_lidar" type="fixed">
    <parent link="body_link"/>
    <child link="lidar_link"/>
    <origin xyz="0 0 0.042"/>
  </joint>

  <link name="rear_link">
    <visual>
      <geometry>
        <mesh filename="package://spot_micro_description/urdf/stl/backpart.stl" scale="0.001 0.001 0.001"/>
      </geometry>
      <origin rpy="0 0 0" xyz="-0.040 -0.060 -0.0140"/>
      <material name="yellow"/>
    </visual>
    <collision>
      <geometry>
        <box size="0.04 0.11 0.07"/>
      </geometry>
      <origin rpy="0 0 0" xyz="0.135 0 0"/>
    </collision>
    <inertial>
      <mass value="0.20"/>
      <inertia ixx="0.000283333" ixy="0" ixz="0" iyy="0.0001083" iyz="0" izz="0.0004033"/>
    </inertial>
  </link>

  <gazebo reference="rear_link">
    <material>Gazebo/Maroon</material>
  </gazebo>

  <joint name="base_rear" type="fixed">
    <parent link="body_link"/>
    <child link="rear_link"/>
  </joint>

  <link name="front_link">
    <visual>
      <geometry>
        <mesh filename="package://spot_micro_description/urdf/stl/frontpart.stl" scale="0.001 0.001 0.001"/>
      </geometry>
      <origin rpy="0 0 0" xyz="-0.040 -0.060 -0.0140"/>
      <material name="yellow"/>
    </visual>
    <collision>
      <geometry>
        <box size="0.058 0.11 0.07"/>
      </geometry>
      <origin rpy="0 0 0" xyz="-0.145 0 0"/>
    </collision>
    <inertial>
      <mass value="0.20"/>
      <inertia ixx="0.0002833" ixy="0" ixz="0" iyy="0.0001377" iyz="0" izz="0.0004033"/>
    </inertial>
  </link>

  <gazebo reference="front_link">
    <material>Gazebo/Maroon</material>
  </gazebo>

  <joint name="base_front" type="fixed">
    <parent link="body_link"/>
    <child link="front_link"/>
  </joint>
  
  <!-- create Legs -->
  <link name="front_left_shoulder_link">
    <visual>
      <geometry>
        <mesh filename="package://spot_micro_description/urdf/stl/lshoulder.stl" scale="0.001 0.001 0.001"/>
      </geometry>
      <origin rpy="0 0 0" xyz="-0.135 -0.02 -0.01"/>
      <material name="black"/>
    </visual>
    <collision>
      <geometry>
        <box size="0.044 0.038 0.07"/>
      </geometry>
      <origin rpy="0 0 0" xyz="0 0 0"/>
    </collision>
    <inertial>
      <mass value="0.10"/>
      <inertia ixx="5.28666e-05" ixy="0" ixz="0" iyy="5.69666e-05" iyz="0" izz="2.40666e-05"/>
    </inertial>
  </link>

  <gazebo reference="front_left_shoulder_link">
    <material>Gazebo/Maroon</material>
  </gazebo>

  <link name="front_left_leg_link_cover">
    <visual>
      <geometry>
        <mesh filename="package://spot_micro_description/urdf/stl/larm_cover.stl" scale="0.001 0.001 0.001"/>
      </geometry>
      <origin rpy="0 0 0" xyz="-0.125 0.04 -0.02"/>
      <material name="yellow"/>
    </visual>
  </link>

  <gazebo reference="front_left_leg_link_cover">
    <material>Gazebo/Maroon</material>
  </gazebo>

  <link name="front_left_leg_link">
    <visual>
      <geometry>
        <mesh filename="package://spot_micro_description/urdf/stl/larm.stl" scale="0.001 0.001 0.001"/>
      </geometry>
      <origin rpy="0 0 0" xyz="-0.125 0.04 -0.02"/>
      <material name="black"/>
      <!--        <geometry>
          <box size="0.028 0.036 ${leg_length}"/>
        </geometry>
        <origin rpy="0.0 0.0 0.0" xyz="0.0 0.0 -0.050"/>
        <material name="yellow"/>-->
    </visual>
    <collision>
      <origin rpy="0.0 0.0 0.0" xyz="0.0 0.0 -0.050"/>
      <geometry>
        <box size="0.028 0.036 0.12"/>
      </geometry>
    </collision>
    <inertial>
      <mass value="0.15"/>
      <inertia ixx="0.00019619" ixy="0" ixz="0" iyy="0.0001898" iyz="0" izz="3.239999e-05"/>
    </inertial>
  </link>

  <gazebo reference="front_left_leg_link">
    <material>Gazebo/Maroon</material>
  </gazebo>

  <link name="front_left_foot_link">
    <visual>
      <geometry>
        <mesh filename="package://spot_micro_description/urdf/stl/lfoot.stl" scale="0.001 0.001 0.001"/>
      </geometry>
      <origin rpy="0 0 0" xyz="-0.120 0.04 0.1"/>
      <material name="black"/>
    </visual>
    <collision>
      <geometry>
        <box size="0.026 0.020 0.115"/>
      </geometry>
      <origin rpy="0.0 0.0 0.0" xyz="0.0 0.0 -0.050"/>
    </collision>
    <inertial>
      <mass value="0.1"/>
      <inertia ixx="0.0001135" ixy="0" ixz="0" iyy="0.00011584" iyz="0" izz="6.666e-06"/>
    </inertial>
  </link>

  <gazebo reference="front_left_foot_link">
    <material>Gazebo/Maroon</material>
  </gazebo>

  <link name="front_left_toe_link">
    <visual>
      <geometry>
        <mesh filename="package://spot_micro_description/urdf/stl/foot.stl" scale="0.001 0.001 0.001"/>
      </geometry>
      <origin rpy="0 -0.40010 0" xyz="0 -0.01 0"/>
      <material name="grey"/>
    </visual>
    <collision>
      <geometry>
        <sphere radius="0.02"/>
      </geometry>
      <origin rpy="0 0 0" xyz="0 0 0"/>
      <contact_coefficients mu="1.1"/>
    </collision>
    <inertial>
      <mass value="0.05"/>
      <inertia ixx="8.00000e-06" ixy="0" ixz="0" iyy="8.00000e-06" iyz="0" izz="8.00000e-06"/>
    </inertial>
  </link>

  <joint name="front_left_shoulder" type="revolute">
    <parent link="body_link"/>
    <child link="front_left_shoulder_link"/>
    <axis xyz="1 0 0"/>
    <origin rpy="0 0 0" xyz="-0.093 -0.036 0"/>
    <limit effort="1000.0" lower="-0.548" upper="0.548" velocity="0.7"/>
    <dynamics damping="0.0" friction="0.5"/>
  </joint>

  <joint name="front_left_leg" type="revolute">
    <parent link="front_left_shoulder_link"/>
    <child link="front_left_leg_link"/>
    <axis xyz="0 1 0"/>
    <origin rpy="0 0 0" xyz="0 -0.052 0"/>
    <limit effort="1000.0" lower="-2.666" upper="1.548" velocity="0.5"/>
    <dynamics damping="0.0" friction="0.0"/>
  </joint>

  <joint name="front_left_leg_cover_joint" type="fixed">
    <parent link="front_left_leg_link"/>
    <child link="front_left_leg_link_cover"/>
    <origin xyz="0 0 0"/>
  </joint>

  <joint name="front_left_foot" type="revolute">
    <parent link="front_left_leg_link"/>
    <child link="front_left_foot_link"/>
    <axis xyz="0 1 0"/>
    <origin rpy="0 0 0" xyz="-0.01 0 -0.12"/>
    <limit effort="1000.0" lower="-0.1" upper="2.59" velocity="0.5"/>
    <dynamics damping="0.0" friction="0.5"/>
  </joint>

  <joint name="front_left_toe" type="fixed">
    <parent link="front_left_foot_link"/>
    <child link="front_left_toe_link"/>
    <origin xyz="0 0 -0.115"/>
  </joint>

  <link name="front_right_shoulder_link">
    <visual>
      <geometry>
        <mesh filename="package://spot_micro_description/urdf/stl/rshoulder.stl" scale="0.001 0.001 0.001"/>
      </geometry>
      <origin rpy="0 0 0" xyz="-0.135 -0.09 -0.01"/>
      <material name="black"/>
    </visual>
    <collision>
      <geometry>
        <box size="0.044 0.038 0.07"/>
      </geometry>
      <origin rpy="0 0 0" xyz="0 0 0"/>
    </collision>
    <inertial>
      <mass value="0.10"/>
      <inertia ixx="5.286666e-05" ixy="0" ixz="0" iyy="5.69666e-05" iyz="0" izz="2.4066e-05"/>
    </inertial>
  </link>

  <link name="front_right_leg_link_cover">
    <visual>
      <geometry>
        <mesh filename="package://spot_micro_description/urdf/stl/rarm_cover.stl" scale="0.001 0.001 0.001"/>
      </geometry>
      <origin rpy="0 0 0" xyz="-0.125 -0.15 -0.02"/>
      <material name="yellow"/>
    </visual>
  </link>

  <gazebo reference="front_right_shoulder_link">
    <material>Gazebo/Maroon</material>
  </gazebo>

  <link name="front_right_leg_link">
    <visual>
      <geometry>
        <mesh filename="package://spot_micro_description/urdf/stl/rarm.stl" scale="0.001 0.001 0.001"/>
      </geometry>
      <origin rpy="0 0 0" xyz="-0.125 -0.15 -0.02"/>
      <material name="black"/>
    </visual>
    <collision>
      <origin rpy="0.0 0.0 0.0" xyz="0.0 0.0 -0.050"/>
      <geometry>
        <box size="0.028 0.036 0.12"/>
      </geometry>
    </collision>
    <inertial>
      <mass value="0.15"/>
      <inertia ixx="0.00019619" ixy="0" ixz="0" iyy="0.0001898" iyz="0" izz="3.23999e-05"/>
    </inertial>
  </link>

  <gazebo reference="front_right_leg_link">
    <material>Gazebo/Maroon</material>
  </gazebo>

  <link name="front_right_foot_link">
    <visual>
      <geometry>
        <mesh filename="package://spot_micro_description/urdf/stl/rfoot.stl" scale="0.001 0.001 0.001"/>
      </geometry>
      <origin rpy="0 0 0" xyz="-0.120 -0.15 0.1"/>
      <material name="black"/>
    </visual>
    <collision>
      <geometry>
        <box size="0.026 0.020 0.115"/>
      </geometry>
      <origin rpy="0.0 0.0 0.0" xyz="0.0 0.0 -0.050"/>
    </collision>
    <inertial>
      <mass value="0.1"/>
      <inertia ixx="0.0001135" ixy="0" ixz="0" iyy="0.0001158" iyz="0" izz="6.6666e-06"/>
    </inertial>
  </link>

  <gazebo reference="front_right_foot_link">
    <material>Gazebo/Maroon</material>
  </gazebo>

  <link name="front_right_toe_link">
    <visual>
      <geometry>
        <mesh filename="package://spot_micro_description/urdf/stl/foot.stl" scale="0.001 0.001 0.001"/>
      </geometry>
      <origin rpy="0 -0.40010 0" xyz="0 -0.01 0"/>
      <material name="grey"/>
    </visual>
    <collision>
      <geometry>
        <sphere radius="0.02"/>
      </geometry>
      <origin rpy="0 0 0" xyz="0 0 0"/>
      <contact_coefficients mu="1.1"/>
    </collision>
    <inertial>
      <mass value="0.05"/>
      <inertia ixx="8.00000e-06" ixy="0" ixz="0" iyy="8.00000e-06" iyz="0" izz="8.00000e-06"/>
    </inertial>
  </link>

  <joint name="front_right_shoulder" type="revolute">
    <parent link="body_link"/>
    <child link="front_right_shoulder_link"/>
    <axis xyz="1 0 0"/>
    <origin rpy="0 0 0" xyz="-0.093 0.036 0"/>
    <limit effort="1000.0" lower="-0.548" upper="0.548" velocity="0.7"/>
    <dynamics damping="0.0" friction="0.5"/>
  </joint>

  <joint name="front_right_leg" type="revolute">
    <parent link="front_right_shoulder_link"/>
    <child link="front_right_leg_link"/>
    <axis xyz="0 1 0"/>
    <origin rpy="0 0 0" xyz="0 0.052 0"/>
    <limit effort="1000.0" lower="-2.666" upper="1.548" velocity="0.5"/>
    <dynamics damping="0.0" friction="0.0"/>
  </joint>

  <joint name="front_right_leg_cover_joint" type="fixed">
    <parent link="front_right_leg_link"/>
    <child link="front_right_leg_link_cover"/>
    <origin xyz="0 0 0"/>
  </joint>

  <joint name="front_right_foot" type="revolute">
    <parent link="front_right_leg_link"/>
    <child link="front_right_foot_link"/>
    <axis xyz="0 1 0"/>
    <origin rpy="0 0 0" xyz="-0.01 0 -0.12"/>
    <limit effort="1000.0" lower="-0.1" upper="2.59" velocity="0.5"/>
    <dynamics damping="0.0" friction="0.5"/>
  </joint>

  <joint name="front_right_toe" type="fixed">
    <parent link="front_right_foot_link"/>
    <child link="front_right_toe_link"/>
    <origin xyz="0 0 -0.115"/>
  </joint>

  <link name="rear_left_shoulder_link">
    <visual>
      <geometry>
        <mesh filename="package://spot_micro_description/urdf/stl/lshoulder.stl" scale="0.001 0.001 0.001"/>
      </geometry>
      <origin rpy="0 0 0" xyz="-0.135 -0.02 -0.01"/>
      <material name="black"/>
    </visual>
    <collision>
      <geometry>
        <box size="0.044 0.038 0.07"/>
      </geometry>
      <origin rpy="0 0 0" xyz="0 0 0"/>
    </collision>
    <inertial>
      <mass value="0.10"/>
      <inertia ixx="5.286666e-05" ixy="0" ixz="0" iyy="5.6966e-05" iyz="0" izz="2.4066e-05"/>
    </inertial>
  </link>

  <gazebo reference="rear_left_shoulder_link">
    <material>Gazebo/Maroon</material>
  </gazebo>

  <link name="rear_left_leg_link_cover">
    <visual>
      <geometry>
        <mesh filename="package://spot_micro_description/urdf/stl/larm_cover.stl" scale="0.001 0.001 0.001"/>
      </geometry>
      <origin rpy="0 0 0" xyz="-0.125 0.04 -0.02"/>
      <material name="yellow"/>
    </visual>
  </link>

  <gazebo reference="rear_left_leg_link_cover">
    <material>Gazebo/Maroon</material>
  </gazebo>

  <link name="rear_left_leg_link">
    <visual>
      <geometry>
        <mesh filename="package://spot_micro_description/urdf/stl/larm.stl" scale="0.001 0.001 0.001"/>
      </geometry>
      <origin rpy="0 0 0" xyz="-0.125 0.04 -0.02"/>
      <material name="black"/>
      <!--        <geometry>
          <box size="0.028 0.036 ${leg_length}"/>
        </geometry>
        <origin rpy="0.0 0.0 0.0" xyz="0.0 0.0 -0.050"/>
        <material name="yellow"/>-->
    </visual>
    <collision>
      <origin rpy="0.0 0.0 0.0" xyz="0.0 0.0 -0.050"/>
      <geometry>
        <box size="0.028 0.036 0.12"/>
      </geometry>
    </collision>
    <inertial>
      <mass value="0.15"/>
      <inertia ixx="0.00019619" ixy="0" ixz="0" iyy="0.0001898" iyz="0" izz="3.23999999e-05"/>
    </inertial>
  </link>

  <gazebo reference="rear_left_leg_link">
      <material>Gazebo/Maroon</material>
  </gazebo>

  <link name="rear_left_foot_link">
    <visual>
      <geometry>
        <mesh filename="package://spot_micro_description/urdf/stl/lfoot.stl" scale="0.001 0.001 0.001"/>
      </geometry>
      <origin rpy="0 0 0" xyz="-0.120 0.04 0.1"/>
      <material name="black"/>
    </visual>
    <collision>
      <geometry>
        <box size="0.026 0.020 0.115"/>
      </geometry>
      <origin rpy="0.0 0.0 0.0" xyz="0.0 0.0 -0.050"/>
    </collision>
    <inertial>
      <mass value="0.1"/>
      <inertia ixx="0.00011354" ixy="0" ixz="0" iyy="0.000115841" iyz="0" izz="6.6666e-06"/>
    </inertial>
  </link>

  <gazebo reference="rear_left_foot_link">
      <material>Gazebo/Maroon</material>
  </gazebo>

  <link name="rear_left_toe_link">
    <visual>
      <geometry>
        <mesh filename="package://spot_micro_description/urdf/stl/foot.stl" scale="0.001 0.001 0.001"/>
      </geometry>
      <origin rpy="0 -0.40010 0" xyz="0 -0.01 0"/>
      <material name="grey"/>
    </visual>
    <collision>
      <geometry>
        <sphere radius="0.02"/>
      </geometry>
      <origin rpy="0 0 0" xyz="0 0 0"/>
      <contact_coefficients mu="1.1"/>
    </collision>
    <inertial>
      <mass value="0.05"/>
      <inertia ixx="8.00000e-06" ixy="0" ixz="0" iyy="8.00000e-06" iyz="0" izz="8.00000e-06"/>
    </inertial>
  </link>

  <joint name="rear_left_shoulder" type="revolute">
    <parent link="body_link"/>
    <child link="rear_left_shoulder_link"/>
    <axis xyz="1 0 0"/>
    <origin rpy="0 0 0" xyz="0.093 -0.036 0"/>
    <limit effort="1000.0" lower="-0.548" upper="0.548" velocity="0.7"/>
    <dynamics damping="0.0" friction="0.5"/>
  </joint>

  <joint name="rear_left_leg" type="revolute">
    <parent link="rear_left_shoulder_link"/>
    <child link="rear_left_leg_link"/>
    <axis xyz="0 1 0"/>
    <origin rpy="0 0 0" xyz="0 -0.052 0"/>
    <limit effort="1000.0" lower="-2.666" upper="1.548" velocity="0.5"/>
    <dynamics damping="0.0" friction="0.0"/>
  </joint>

  <joint name="rear_left_leg_cover_joint" type="fixed">
    <parent link="rear_left_leg_link"/>
    <child link="rear_left_leg_link_cover"/>
    <origin xyz="0 0 0"/>
  </joint>

  <joint name="rear_left_foot" type="revolute">
    <parent link="rear_left_leg_link"/>
    <child link="rear_left_foot_link"/>
    <axis xyz="0 1 0"/>
    <origin rpy="0 0 0" xyz="-0.01 0 -0.12"/>
    <limit effort="1000.0" lower="-0.1" upper="2.59" velocity="0.5"/>
    <dynamics damping="0.0" friction="0.5"/>
  </joint>

  <joint name="rear_left_toe" type="fixed">
    <parent link="rear_left_foot_link"/>
    <child link="rear_left_toe_link"/>
    <origin xyz="0 0 -0.115"/>
  </joint>
  
  <link name="rear_right_shoulder_link">
    <visual>
      <geometry>
        <mesh filename="package://spot_micro_description/urdf/stl/rshoulder.stl" scale="0.001 0.001 0.001"/>
      </geometry>
      <origin rpy="0 0 0" xyz="-0.135 -0.09 -0.01"/>
      <material name="black"/>
    </visual>
    <collision>
      <geometry>
        <box size="0.044 0.038 0.07"/>
      </geometry>
      <origin rpy="0 0 0" xyz="0 0 0"/>
    </collision>
    <inertial>
      <mass value="0.10"/>
      <inertia ixx="5.28666e-05" ixy="0" ixz="0" iyy="5.6966e-05" iyz="0" izz="2.4066e-05"/>
    </inertial>
  </link>

  <gazebo reference="rear_right_shoulder_link">
    <material>Gazebo/Maroon</material>
  </gazebo>

  <link name="rear_right_leg_link_cover">
    <visual>
      <geometry>
        <mesh filename="package://spot_micro_description/urdf/stl/rarm_cover.stl" scale="0.001 0.001 0.001"/>
      </geometry>
      <origin rpy="0 0 0" xyz="-0.125 -0.15 -0.02"/>
      <material name="yellow"/>
    </visual>
  </link>

  <gazebo reference="rear_right_leg_link_cover">
    <material>Gazebo/Maroon</material>
  </gazebo>

  <link name="rear_right_leg_link">
    <visual>
      <geometry>
        <mesh filename="package://spot_micro_description/urdf/stl/rarm.stl" scale="0.001 0.001 0.001"/>
      </geometry>
      <origin rpy="0 0 0" xyz="-0.125 -0.15 -0.02"/>
      <material name="black"/>
      <!--        <geometry>
          <box size="0.028 0.036 ${leg_length}"/>
        </geometry>
        <origin rpy="0.0 0.0 0.0" xyz="0.0 0.0 -0.050"/>
        <material name="yellow"/>-->
    </visual>
    <collision>
      <origin rpy="0.0 0.0 0.0" xyz="0.0 0.0 -0.050"/>
      <geometry>
        <box size="0.028 0.036 0.12"/>
      </geometry>
    </collision>
    <inertial>
      <mass value="0.15"/>
      <inertia ixx="0.0001961999" ixy="0" ixz="0" iyy="0.0001898" iyz="0" izz="3.239999e-05"/>
    </inertial>
  </link>

  <gazebo reference="rear_right_leg_link">
    <material>Gazebo/Maroon</material>
  </gazebo>

  <link name="rear_right_foot_link">
    <visual>
      <geometry>
        <mesh filename="package://spot_micro_description/urdf/stl/rfoot.stl" scale="0.001 0.001 0.001"/>
      </geometry>
      <origin rpy="0 0 0" xyz="-0.120 -0.15 0.1"/>
      <material name="black"/>
    </visual>
    <collision>
      <geometry>
        <box size="0.026 0.020 0.115"/>
      </geometry>
      <origin rpy="0.0 0.0 0.0" xyz="0.0 0.0 -0.050"/>
    </collision>
    <inertial>
      <mass value="0.1"/>
      <inertia ixx="0.000113541" ixy="0" ixz="0" iyy="0.000115841" iyz="0" izz="6.66666e-06"/>
    </inertial>
  </link>

  <gazebo reference="rear_right_foot_link">
    <material>Gazebo/Maroon</material>
  </gazebo>

  <link name="rear_right_toe_link">
    <visual>
      <geometry>
        <mesh filename="package://spot_micro_description/urdf/stl/foot.stl" scale="0.001 0.001 0.001"/>
      </geometry>
      <origin rpy="0 -0.40010 0" xyz="0 -0.01 0"/>
      <material name="grey"/>
    </visual>
    <collision>
      <geometry>
        <sphere radius="0.02"/>
      </geometry>
      <origin rpy="0 0 0" xyz="0 0 0"/>
      <contact_coefficients mu="1.1"/>
    </collision>
    <inertial>
      <mass value="0.05"/>
      <inertia ixx="8.00000e-06" ixy="0" ixz="0" iyy="8.00000e-06" iyz="0" izz="8.00000e-06"/>
    </inertial>
  </link>

  <joint name="rear_right_shoulder" type="revolute">
    <parent link="body_link"/>
    <child link="rear_right_shoulder_link"/>
    <axis xyz="1 0 0"/>
    <origin rpy="0 0 0" xyz="0.093 0.036 0"/>
    <limit effort="1000.0" lower="-0.548" upper="0.548" velocity="0.7"/>
    <dynamics damping="0.0" friction="0.5"/>
  </joint>

  <joint name="rear_right_leg" type="revolute">
    <parent link="rear_right_shoulder_link"/>
    <child link="rear_right_leg_link"/>
    <axis xyz="0 1 0"/>
    <origin rpy="0 0 0" xyz="0 0.052 0"/>
    <limit effort="1000.0" lower="-2.666" upper="1.548" velocity="0.5"/>
    <dynamics damping="0.0" friction="0.0"/>
  </joint>

  <joint name="rear_right_leg_cover_joint" type="fixed">
    <parent link="rear_right_leg_link"/>
    <child link="rear_right_leg_link_cover"/>
    <origin xyz="0 0 0"/>
  </joint>

  <joint name="rear_right_foot" type="revolute">
    <parent link="rear_right_leg_link"/>
    <child link="rear_right_foot_link"/>
    <axis xyz="0 1 0"/>
    <origin rpy="0 0 0" xyz="-0.01 0 -0.12"/>
    <limit effort="1000.0" lower="-0.1" upper="2.59" velocity="0.5"/>
    <dynamics damping="0.0" friction="0.5"/>
  </joint>

  <joint name="rear_right_toe" type="fixed">
    <parent link="rear_right_foot_link"/>
    <child link="rear_right_toe_link"/>
    <origin xyz="0 0 -0.115"/>
  </joint>

  <gazebo reference="rear_left_toe_link">
      <kp>1000000000000000000000000000.0</kp>
      <kd>1000000000000000000000000000.0</kd>
      <mu1>10.0</mu1>
      <mu2>10.0</mu2>
      <material>Gazebo/Orange</material>
  </gazebo>

  <gazebo reference="rear_right_toe_link">
      <kp>1000000000000000000000000000.0</kp>
      <kd>1000000000000000000000000000.0</kd>
      <mu1>10.0</mu1>
      <mu2>10.0</mu2>
      <material>Gazebo/Orange</material>
  </gazebo>

  <gazebo reference="front_right_toe_link">
      <kp>1000000000000000000000000000.0</kp>
      <kd>1000000000000000000000000000.0</kd>
      <mu1>10.0</mu1>
      <mu2>10.0</mu2>
      <material>Gazebo/Orange</material>
  </gazebo>
  
  <gazebo reference="front_left_toe_link">
      <kp>1000000000000000000000000000.0</kp>
      <kd>1000000000000000000000000000.0</kd>
      <mu1>10.0</mu1>
      <mu2>10.0</mu2>
      <material>Gazebo/Orange</material>
  </gazebo>

  <gazebo reference="lidar_link">
    <sensor name="lidar" type="ray">
      <always_on>true</always_on>
      <visualize>true</visualize>
      <update_rate>5</update_rate>
      <ray>
        <scan>
          <horizontal>
            <samples>360</samples>
            <resolution>1.000000</resolution>
            <min_angle>0.000000</min_angle>
            <max_angle>6.280000</max_angle>
          </horizontal>
        </scan>
        <range>
          <min>0.120000</min>
          <max>3.5</max>
          <resolution>0.015000</resolution>
        </range>
        <noise>
          <type>gaussian</type>
          <mean>0.0</mean>
          <stddev>0.01</stddev>
        </noise>
      </ray>
      <plugin name="scan" filename="libgazebo_ros_ray_sensor.so">
        <ros>
          <remapping>~/out:=scan</remapping>
        </ros>
        <output_type>sensor_msgs/LaserScan</output_type>
        <frame_name>lidar_link</frame_name>
      </plugin>
    </sensor>
  </gazebo>

  <!-- JOINT PUBLISHER -->
  <gazebo>
    <plugin name="quadruped_joint_state" filename="libgazebo_ros_joint_state_publisher.so">
      <ros>
        <remapping>~/out:=joint_states</remapping>
      </ros>
      <update_rate>30</update_rate>

      <joint_name>front_left_shoulder</joint_name>
      <joint_name>front_left_leg</joint_name>
      <joint_name>front_left_foot</joint_name>

      <joint_name>front_right_shoulder</joint_name>
      <joint_name>front_right_leg</joint_name>             
      <joint_name>front_right_foot</joint_name>

      <joint_name>rear_left_shoulder</joint_name>
      <joint_name>rear_left_leg</joint_name>
      <joint_name>rear_left_foot</joint_name>  

      <joint_name>rear_right_shoulder</joint_name>          
      <joint_name>rear_right_foot</joint_name>
      <joint_name>rear_right_leg</joint_name>
    </plugin>
  </gazebo>

  <ros2_control name="GazeboSystem" type="System">
    <hardware>
      <plugin>gazebo_ros2_control/GazeboSystem</plugin>
    </hardware>
   
    <joint name="front_right_shoulder">
      <command_interface name="position">
        <param name="min">-3.14</param>
        <param name="max">3.14</param>
      </command_interface>
      <state_interface name="position"/>
      <state_interface name="effort"/>
      <state_interface name="velocity"/>
    </joint>

    <joint name="front_right_leg">
      <command_interface name="position">
        <param name="min">-3.14</param>
        <param name="max">3.14</param>
      </command_interface>
      <state_interface name="position"/>
      <state_interface name="velocity"/>
      <state_interface name="effort"/>
    </joint>

    <joint name="front_right_foot">
      <command_interface name="position">
        <param name="min">-3.14</param>
        <param name="max">3.14</param>
      </command_interface>
      <state_interface name="position"/>
      <state_interface name="velocity"/>
      <state_interface name="effort"/>
    </joint>

    <joint name="front_left_shoulder">
      <command_interface name="position">
        <param name="min">-3.14</param>
        <param name="max">3.14</param>
      </command_interface>
      <state_interface name="position"/>
      <state_interface name="velocity"/>
      <state_interface name="effort"/>
    </joint>

    <joint name="front_left_leg">
      <command_interface name="position">
        <param name="min">-3.14</param>
        <param name="max">3.14</param>
      </command_interface>
      <state_interface name="position"/>
      <state_interface name="velocity"/>
      <state_interface name="effort"/>
    </joint>

    <joint name="front_left_foot">
      <command_interface name="position">
        <param name="min">-3.14</param>
        <param name="max">3.14</param>
      </command_interface>
      <state_interface name="position"/>
      <state_interface name="velocity"/>
      <state_interface name="effort"/>
    </joint>

        <joint name="rear_right_shoulder">
      <command_interface name="position">
        <param name="min">-3.14</param>
        <param name="max">3.14</param>
      </command_interface>
      <state_interface name="position"/>
      <state_interface name="effort"/>
      <state_interface name="velocity"/>
    </joint>

    <joint name="rear_right_leg">
      <command_interface name="position">
        <param name="min">-3.14</param>
        <param name="max">3.14</param>
      </command_interface>
      <state_interface name="position"/>
      <state_interface name="velocity"/>
      <state_interface name="effort"/>
    </joint>

    <joint name="rear_right_foot">
      <command_interface name="position">
        <param name="min">-3.14</param>
        <param name="max">3.14</param>
      </command_interface>
      <state_interface name="position"/>
      <state_interface name="velocity"/>
      <state_interface name="effort"/>
    </joint>

    <joint name="rear_left_shoulder">
      <command_interface name="position">
        <param name="min">-3.14</param>
        <param name="max">3.14</param>
      </command_interface>
      <state_interface name="position"/>
      <state_interface name="velocity"/>
      <state_interface name="effort"/>
    </joint>

    <joint name="rear_left_leg">
      <command_interface name="position">
        <param name="min">-3.14</param>
        <param name="max">3.14</param>
      </command_interface>
      <state_interface name="position"/>
      <state_interface name="velocity"/>
      <state_interface name="effort"/>
    </joint>

    <joint name="rear_left_foot">
      <command_interface name="position">
        <param name="min">-3.14</param>
        <param name="max">3.14</param>
      </command_interface>
      <state_interface name="position"/>
      <state_interface name="velocity"/>
      <state_interface name="effort"/>
    </joint>
  </ros2_control>

  <gazebo>
      <plugin filename="libgazebo_ros2_control.so" name="gazebo_ros2_control">
          <parameters>$(find spot_micro_control)/config/robot_controller.yaml</parameters>
          <robot_param_node>my_robot_state_publisher_node</robot_param_node>
      </plugin>
  </gazebo>   
</robot>

